2022-01-03 17:53:18,014 INFO    MainThread:5426 [wandb_setup.py:_flush():71] setting env: {}
2022-01-03 17:53:18,015 INFO    MainThread:5426 [wandb_setup.py:_flush():71] setting login settings: {}
2022-01-03 17:53:18,015 INFO    MainThread:5426 [wandb_init.py:_log_setup():371] Logging user logs to /home/aiotlabws/Workspace/Project/hungvv/stdgi/wandb/run-20220103_175318-33b7zlkn/logs/debug.log
2022-01-03 17:53:18,015 INFO    MainThread:5426 [wandb_init.py:_log_setup():372] Logging internal logs to /home/aiotlabws/Workspace/Project/hungvv/stdgi/wandb/run-20220103_175318-33b7zlkn/logs/debug-internal.log
2022-01-03 17:53:18,016 INFO    MainThread:5426 [wandb_init.py:init():404] calling init triggers
2022-01-03 17:53:18,016 INFO    MainThread:5426 [wandb_init.py:init():409] wandb.init called with sweep_config: {}
config: {'seed': 52, 'train_station': [0, 1, 2, 3, 4, 5, 6, 7, 8, 9, 10, 11, 12, 13, 14, 15, 16, 17, 18, 19], 'test_station': [21, 22, 23, 24, 25, 26, 27, 28, 29], 'input_dim': 9, 'output_dim': 1, 'sequence_length': 12, 'batch_size': 32, 'patience': 3, 'lr_stdgi': 0.005, 'num_epochs_stdgi': 1, 'output_stdgi': 60, 'checkpoint_stdgi': './out/checkpoint/stdgi.pt', 'output_path': './out/', 'en_hid1': 200, 'en_hid2': 400, 'dis_hid': 6, 'act_fn': 'relu', 'delta_stdgi': 0, 'num_epochs_decoder': 1, 'lr_decoder': 0.005, 'checkpoint_decoder': './out/checkpoint/decoder.pt', 'delta_decoder': 0, 'cnn_hid_dim': 128, 'fc_hid_dim': 64, 'rnn_type': 'LSTM', 'n_layers_rnn': 1, 'interpolate': False, 'attention_decoder': False, 'features': ['PM2.5', 'AQI', 'PM10', 'CO', 'O3', 'SO2', 'NO2', 'Change', 'wind'], 'loss': 'linex_loss'}
2022-01-03 17:53:18,016 INFO    MainThread:5426 [wandb_init.py:init():460] starting backend
2022-01-03 17:53:18,016 INFO    MainThread:5426 [backend.py:_multiprocessing_setup():99] multiprocessing start_methods=fork,spawn,forkserver, using: spawn
2022-01-03 17:53:18,026 INFO    MainThread:5426 [backend.py:ensure_launched():216] starting backend process...
2022-01-03 17:53:18,033 INFO    MainThread:5426 [backend.py:ensure_launched():221] started backend process with pid: 5529
2022-01-03 17:53:18,035 INFO    MainThread:5426 [wandb_init.py:init():469] backend started and connected
2022-01-03 17:53:18,040 INFO    MainThread:5426 [wandb_init.py:init():533] updated telemetry
2022-01-03 17:53:18,060 INFO    MainThread:5426 [wandb_init.py:init():563] communicating current version
2022-01-03 17:53:18,838 INFO    MainThread:5426 [wandb_init.py:init():568] got version response 
2022-01-03 17:53:18,838 INFO    MainThread:5426 [wandb_init.py:init():578] communicating run to backend with 30 second timeout
2022-01-03 17:53:19,287 INFO    MainThread:5426 [wandb_init.py:init():606] starting run threads in backend
2022-01-03 17:53:21,514 INFO    MainThread:5426 [wandb_run.py:_console_start():1810] atexit reg
2022-01-03 17:53:21,514 INFO    MainThread:5426 [wandb_run.py:_redirect():1684] redirect: SettingsConsole.REDIRECT
2022-01-03 17:53:21,515 INFO    MainThread:5426 [wandb_run.py:_redirect():1689] Redirecting console.
2022-01-03 17:53:21,517 INFO    MainThread:5426 [wandb_run.py:_redirect():1745] Redirects installed.
2022-01-03 17:53:21,517 INFO    MainThread:5426 [wandb_init.py:init():633] run started, returning control to user process
2022-01-03 17:53:26,710 INFO    MainThread:5426 [wandb_watch.py:watch():43] Watching
2022-01-03 17:55:04,339 INFO    MainThread:5426 [wandb_watch.py:watch():43] Watching
2022-01-03 17:56:25,462 ERROR   MainThread:5426 [util.py:get_module():187] Error importing optional module plotly.tools
Traceback (most recent call last):
  File "/home/aiotlabws/Workspace/Env/anaconda3/envs/longnd/lib/python3.8/site-packages/wandb/util.py", line 182, in get_module
    return import_module(name)
  File "/home/aiotlabws/Workspace/Env/anaconda3/envs/longnd/lib/python3.8/importlib/__init__.py", line 127, in import_module
    return _bootstrap._gcd_import(name[level:], package, level)
  File "<frozen importlib._bootstrap>", line 1014, in _gcd_import
  File "<frozen importlib._bootstrap>", line 991, in _find_and_load
  File "<frozen importlib._bootstrap>", line 961, in _find_and_load_unlocked
  File "<frozen importlib._bootstrap>", line 219, in _call_with_frames_removed
  File "<frozen importlib._bootstrap>", line 1014, in _gcd_import
  File "<frozen importlib._bootstrap>", line 991, in _find_and_load
  File "<frozen importlib._bootstrap>", line 973, in _find_and_load_unlocked
ModuleNotFoundError: No module named 'plotly'
2022-01-03 17:56:25,465 INFO    MainThread:5426 [wandb_run.py:_atexit_cleanup():1780] got exitcode: 1
2022-01-03 17:56:25,467 INFO    MainThread:5426 [wandb_run.py:_restore():1752] restore
2022-01-03 17:56:31,298 ERROR   MainThread:5426 [wandb_run.py:_atexit_cleanup():1798] Problem finishing run
Traceback (most recent call last):
  File "/home/aiotlabws/Workspace/Env/anaconda3/envs/longnd/lib/python3.8/site-packages/wandb/sdk/wandb_run.py", line 1788, in _atexit_cleanup
    self._on_finish()
  File "/home/aiotlabws/Workspace/Env/anaconda3/envs/longnd/lib/python3.8/site-packages/wandb/sdk/wandb_run.py", line 1934, in _on_finish
    self.history._flush()
  File "/home/aiotlabws/Workspace/Env/anaconda3/envs/longnd/lib/python3.8/site-packages/wandb/sdk/wandb_history.py", line 59, in _flush
    self._callback(row=self._data, step=self._step)
  File "/home/aiotlabws/Workspace/Env/anaconda3/envs/longnd/lib/python3.8/site-packages/wandb/sdk/wandb_run.py", line 1017, in _history_callback
    self._backend.interface.publish_history(
  File "/home/aiotlabws/Workspace/Env/anaconda3/envs/longnd/lib/python3.8/site-packages/wandb/sdk/interface/interface.py", line 496, in publish_history
    data = data_types.history_dict_to_json(run, data, step=step)
  File "/home/aiotlabws/Workspace/Env/anaconda3/envs/longnd/lib/python3.8/site-packages/wandb/sdk/data_types.py", line 2597, in history_dict_to_json
    payload[key] = val_to_json(run, key, val, namespace=step)
  File "/home/aiotlabws/Workspace/Env/anaconda3/envs/longnd/lib/python3.8/site-packages/wandb/sdk/data_types.py", line 2622, in val_to_json
    val = Plotly.make_plot_media(val)
  File "/home/aiotlabws/Workspace/Env/anaconda3/envs/longnd/lib/python3.8/site-packages/wandb/sdk/data_types.py", line 2547, in make_plot_media
    val = util.matplotlib_to_plotly(val)
  File "/home/aiotlabws/Workspace/Env/anaconda3/envs/longnd/lib/python3.8/site-packages/wandb/util.py", line 506, in matplotlib_to_plotly
    tools = get_module(
  File "/home/aiotlabws/Workspace/Env/anaconda3/envs/longnd/lib/python3.8/site-packages/wandb/util.py", line 189, in get_module
    raise wandb.Error(required)
wandb.errors.Error: plotly is required to log interactive plots, install with: pip install plotly or convert the plot to an image with `wandb.Image(plt)`
